<?xml version="1.0" encoding="utf-8"?>
<!-- This URDF was automatically created by SolidWorks to URDF Exporter! Originally created by Stephen Brawner (brawner@gmail.com) 
     Commit Version: 1.6.0-4-g7f85cfe  Build Version: 1.6.7995.38578
     For more information, please see http://wiki.ros.org/sw_urdf_exporter -->
<robot
  name="montyurdf">
  <link
    name="base_link">
    <inertial>
      <origin
        xyz="0.00200827848538973 1.38777878078145E-17 0.0248803053149128"
        rpy="0 0 0" />
      <mass
        value="1.88328535462952" />
      <inertia
        ixx="0.00380488197395567"
        ixy="-2.51785616917292E-18"
        ixz="1.87010383014531E-05"
        iyy="0.00993131373336837"
        iyz="-1.43773143418147E-20"
        izz="0.0129409263196975" />
    </inertial>
    <visual>
      <origin
        xyz="0 0 0"
        rpy="0 0 0" />
      <geometry>
        <mesh
          filename="package://montyurdf/meshes/base_link.STL" />
      </geometry>
      <material
        name="">
        <color
          rgba="1 1 1 1" />
      </material>
    </visual>
    <collision>
      <origin
        xyz="0 0 0"
        rpy="0 0 0" />
      <geometry>
        <mesh
          filename="package://montyurdf/meshes/base_link.STL" />
      </geometry>
    </collision>
  </link>
  <link
    name="left_wheel_link">
    <inertial>
      <origin
        xyz="-5.55111512312578E-17 2.77555756156289E-17 -1.38777878078145E-17"
        rpy="0 0 0" />
      <mass
        value="0.11487302445888" />
      <inertia
        ixx="4.35510284479888E-05"
        ixy="9.54295386760082E-20"
        ixz="-1.70736763465032E-37"
        iyy="7.00262974944061E-05"
        iyz="-1.46936793852786E-36"
        izz="4.35510284479888E-05" />
    </inertial>
    <visual>
      <origin
        xyz="0 0 0"
        rpy="0 0 0" />
      <geometry>
        <mesh
          filename="package://montyurdf/meshes/left_wheel_link.STL" />
      </geometry>
      <material
        name="">
        <color
          rgba="0.298039215686275 0.298039215686275 0.298039215686275 1" />
      </material>
    </visual>
    <collision>
      <origin
        xyz="0 0 0"
        rpy="0 0 0" />
      <geometry>
        <mesh
          filename="package://montyurdf/meshes/left_wheel_link.STL" />
      </geometry>
    </collision>
  </link>
  <joint
    name="leftWheelJoint"
    type="continuous">
    <origin
      xyz="-0.066858 0.095 0.015"
      rpy="0 0 0" />
    <parent
      link="base_link" />
    <child
      link="left_wheel_link" />
    <axis
      xyz="0 1 0" />
    <limit
      effort="1"
      velocity="1" />
  </joint>
  <link
    name="right_wheel_link">
    <inertial>
      <origin
        xyz="-5.55111512312578E-17 3.46944695195361E-18 0"
        rpy="0 0 0" />
      <mass
        value="0.11487302445888" />
      <inertia
        ixx="4.35510284479888E-05"
        ixy="9.67437890580536E-20"
        ixz="-1.7073676346503E-37"
        iyy="7.00262974944061E-05"
        iyz="-3.67341984631964E-37"
        izz="4.35510284479888E-05" />
    </inertial>
    <visual>
      <origin
        xyz="0 0 0"
        rpy="0 0 0" />
      <geometry>
        <mesh
          filename="package://montyurdf/meshes/right_wheel_link.STL" />
      </geometry>
      <material
        name="">
        <color
          rgba="0.298039215686275 0.298039215686275 0.298039215686275 1" />
      </material>
    </visual>
    <collision>
      <origin
        xyz="0 0 0"
        rpy="0 0 0" />
      <geometry>
        <mesh
          filename="package://montyurdf/meshes/right_wheel_link.STL" />
      </geometry>
    </collision>
  </link>
  <joint
    name="rightWheelJoint"
    type="continuous">
    <origin
      xyz="-0.066858 -0.095 0.015"
      rpy="0 0 0" />
    <parent
      link="base_link" />
    <child
      link="right_wheel_link" />
    <axis
      xyz="0 1 0" />
    <limit
      effort="1"
      velocity="1" />
  </joint>
</robot>